Workbook

Sheet Contents
A1: MINIMUM DATASET FOR ADULT PROTECTION COMMITTEES: VERSION 1.1 (MID 2026) | LA1: — PLEASE SELECT —
KZ2: 1 | LA2: Aberdeen City
A3: LOCAL AUTHORITY AREA | KZ3: 2 | LA3: Aberdeenshire
KZ4: 3 | LA4: Angus
B5: — PLEASE SELECT — | KZ5: 4 | LA5: Argyll and Bute
A6: Please select your Local Authority area from the list above. | KZ6: 5 | LA6: City of Edinburgh
KZ7: 6 | LA7: Clackmannanshire
A8: NAMED CONTACT | KZ8: 7 | LA8: Dumfries and Galloway
A9: Please provide a named contact for the ASP Minimum Dataset here. This person will be notified of any key updates in addition to the Lead Officer in your area. | KZ9: 8 | LA9: Dundee City
B10: NAME: | KZ10: 9 | LA10: East Ayrshire
B11: E-MAIL: | KZ11: 10 | LA11: East Dunbartonshire
KZ12: 11 | LA12: East Lothian
KZ13: 12 | LA13: East Renfrewshire
A14: NOTES | KZ14: 13 | LA14: Falkirk
A15: Please note that, for all indicators, two quarters worth of demonstration data (marked in gray) has been included. This is not real data, will not be counted as part of your submission and is included for illustrative purposes only. | KZ15: 14 | LA15: Fife
A16: Please return a copy of the completed workbook to the address below on the agreed dates. ASPData@gov.scot | KZ16: 15 | LA16: Glasgow City
KZ17: 16 | LA17: Highland
A18: CONTENTS | KZ18: 17 | LA18: Inverclyde
A19: ='Notes on chart use'!A1 -> Supplemental | C19: ='Notes on chart use'!C1 -> NOTES ON CHART USAGE (PLEASE READ)
A20: INVOLVEMENT IN ASP PROCESSES | KZ20: 18 | LA20: Midlothian
A21: ='1 ASP REFERRALS'!A1 -> Indicator 1 | C21: =('1 ASP REFERRALS'!C1) -> ASP REFERRALS SUBMITTED TO ADULT PROTECTION SERVICE (BY SOURCE) | KZ21: 19 | LA21: Moray
A22: ='2-3 INQUIRIES'!A1 -> Indicator 2 | C22: ='2-3 INQUIRIES'!C1 -> INQUIRIES UNDERTAKEN WITHOUT THE USE OF INVESTIGATORY POWERS | KZ22: 20 | LA22: Na h-Eileanan Siar
A23: ='2-3 INQUIRIES'!A2 -> Indicator 3 | C23: ='2-3 INQUIRIES'!C2 -> INQUIRIES UNDERTAKEN WITH THE USE OF INVESTIGATORY POWERS | KZ23: 21 | LA23: North Ayrshire
A24: ='Conversion data'!A1 -> Supplemental | C24: ='Conversion data'!C1 -> CONVERSION RATES OF REFERRALS TO INQUIRIES
A25: MULTI-AGENCY ADULT SUPPORT AND PROTECTION CONFERENCES (CASE CONFERENCES) | KZ25: 22 | LA25: North Lanarkshire
A26: {='4 CCs'!A1:A2} -> Indicator 4a | C26: {=('4 CCs'!C1:C2)} -> INITIAL CASE CONFERENCES | KZ26: 23 | LA26: Orkney Islands
A27: Indicator 4b | C27: REVIEW CASE CONFERENCES | KZ27: 24 | LA27: Perth and Kinross
A28: {='5-7 CC ATTENDEES'!A1:A4} -> Indicator 5a | C28: {=('5-7 CC ATTENDEES'!C1:C4)} -> ADULTS AT RISK INVITED TO ATTEND A CASE CONFERENCE (TOTAL) | KZ28: 25 | LA28: Renfrewshire
A29: Indicator 5b | C29: ADULTS AT RISK INVITED TO ATTEND A CASE CONFERENCE (PERCENTAGE UPTAKE) | KZ29: 26 | LA29: Scottish Borders
A30: Indicator 6a | C30: INDEPENDENT ADVOCATES INVITED TO ATTEND A CASE CONFERENCE (TOTAL) | KZ30: 27 | LA30: Shetland Islands
A31: Indicator 6b | C31: INDEPENDENT ADVOCATES INVITED TO ATTEND A CASE CONFERENCE (PERCENTAGE UPTAKE) | KZ31: 28 | LA31: South Ayrshire
A32: ADULT SUPPORT AND PROTECTION PLANS AND USE OF POWERS | KZ32: 29 | LA32: South Lanarkshire
A33: ='8-9 ASPPs & POWERS'!A1 -> Indicator 8a | C33: =('8-9 ASPPs & POWERS'!C1) -> NUMBER OF ADULTS ON ASPPs IN TOTAL AT END OF QUARTER | KZ33: 30 | LA33: Stirling
A34: ='8-9 ASPPs & POWERS'!A2 -> Indicator 8b | C34: =('8-9 ASPPs & POWERS'!C2) -> NUMBER OF ADULTS WITH NEWLY COMMENCED ASPPs WITHIN QUARTER ONLY | KZ34: 31 | LA34: West Dunbartonshire
A35: ='8-9 ASPPs & POWERS'!A3 -> Indicator 9a | C35: =('8-9 ASPPs & POWERS'!C3) -> PROTECTION ORDERS (APPLIED FOR) | KZ35: 32 | LA35: West Lothian
A36: ='8-9 ASPPs & POWERS'!A4 -> Indicator 9b | C36: =('8-9 ASPPs & POWERS'!C4) -> PROTECTION ORDERS (GRANTED)
A37: ='10-11 ACTIONS TAKEN'!A1 -> Indicator 10 | C37: =('10-11 ACTIONS TAKEN'!C1) -> ACTION TAKEN FOLLOWING INQUIRIES CONCLUDED WITHOUT THE USE OF INVESTIGATORY POWERS
A38: ='10-11 ACTIONS TAKEN'!A2 -> Indicator 11 | C38: =('10-11 ACTIONS TAKEN'!C2) -> ACTION TAKEN FOLLOWING INQUIRIES USING INVESTIGATORY POWERS
A39: DEMOGRAPHICS AND DESCRIPTIVE DATA
A40: ='13 AGE & GENDER'!A1 -> Indicator 13 | C40: ='13 AGE & GENDER'!C1 -> AGE GROUP AND GENDER (FOR ALL INQUIRIES)
...

Sheet Notes on chart use
A1: Supplemental | C1: NOTES ON CHART USAGE (PLEASE READ)
C3: The charts included in the workbook are intended to be used in conjunction with the supplied reporting template. Their use is optional, and should be considered as a starting point from which to develop a reporting system that best suits your local needs.
C5: The colour scheme utilised is derived from the Scottish Government colour palette for categorical data. However, it has been necessary to expand upon that palette in order to meet the requirements of the dataset. The additional colours also meet the 3:1 contrast ratios of the originals.
C7: More information can be found online at https://designsystem.gov.scot/guidance/charts/data-visualisation-colour-palettes
C9: The number of quarters included in each chart can be adjusted or increased by selecting each data series, and moving the cells (this is a limitation of Excel). We recommend that no more than three years worth of data be featured at a time.
C11: Where relevant, the values of the vertical axis will adjust automatically based on the values recorded. Be aware that some charts, by necessity, pull data from helper tables that were added to the workbook for that purpose.
C13: When copying charts over to the template, we strongly recommend adding them as pictures. This will avoid issues should the path between the template and workbook change, or should the latter be renamed, for example. Instructions are provided below.
C15: Pasting an Excel chart into Word as a picture
C17: Step 1 — Copy the chart in Excel
C19: 1. Click once on the chart to select it (you'll see handles appear around the edge).
C20: 2. Press Ctrl+C (Windows) or Cmd+C (Mac) to copy it.
C22: Step 2 — Paste as a picture in Word
C24: 1. Click in the template where you want the chart to appear.
... C58: * The original Excel workbook is unaffected by this process; this creates a separate copy.

Sheet 1 ASP REFERRALS
A1: Indicator 1 | C1: ASP REFERRALS SUBMITTED TO ADULT PROTECTION SERVICE (BY SOURCE)
A3: LOCAL DATA
A4: =A1 -> Indicator 1 | C4: Apr-Jun | D4: Jul-Sep | E4: Oct-Dec | F4: Jan-Mar | G4: Apr-Jun | H4: Jul-Sep | I4: Oct-Dec | J4: Jan-Mar | K4: Apr-Jun | L4: Jul-Sep | M4: Oct-Dec | N4: Jan-Mar | O4: Apr-Jun | P4: Jul-Sep | Q4: Oct-Dec | R4: Jan-Mar | S4: Apr-Jun | T4: Jul-Sep | U4: Oct-Dec | V4: Jan-Mar | W4: Apr-Jun | X4: Jul-Sep | Y4: Oct-Dec | Z4: Jan-Mar | AA4: Apr-Jun | AB4: Jul-Sep | AC4: Oct-Dec | AD4: Jan-Mar | AE4: Apr-Jun | AF4: Jul-Sep | AG4: Oct-Dec | AH4: Jan-Mar | AI4: Apr-Jun | AJ4: Jul-Sep | AK4: Oct-Dec | AL4: Jan-Mar
C5: Q1 2023/24 | D5: Q2 2023/24 | E5: Q3 2023/24 | F5: Q4 2023/24 | G5: Q1 2024/25 | H5: Q2 2024/25 | I5: Q3 2024/25 | J5: Q4 2024/25 | K5: Q1 2025/26 | L5: Q2 2025/26 | M5: Q3 2025/26 | N5: Q4 2025/26 | O5: Q1 2026/27 | P5: Q2 2026/27 | Q5: Q3 2026/27 | R5: Q4 2026/27 | S5: Q1 2027/28 | T5: Q2 2027/28 | U5: Q3 2027/28 | V5: Q4 2027/28 | W5: Q1 2028/29 | X5: Q2 2028/29 | Y5: Q3 2028/29 | Z5: Q4 2028/29 | AA5: Q1 2029/30 | AB5: Q2 2029/30 | AC5: Q3 2029/30 | AD5: Q4 2029/30 | AE5: Q1 2030/31 | AF5: Q2 2030/31 | AG5: Q3 2030/31 | AH5: Q4 2030/31 | AI5: Q1 2031/32 | AJ5: Q2 2031/32 | AK5: Q3 2031/32 | AL5: Q4 2031/32
A6: Mental Welfare Commission for Scotland
A7: Care Inspectorate
A8: Healthcare Improvement Scotland
A9: Office of the Public Guardian
A10: Police Scotland
A11: NHS 24
A12: NHS Primary Care
A13: NHS Acute Services
A14: NHS Specialist Drug and Alcohol Services
A15: NHS Community Health Services
A16: Mental Health Services – Hospital and Community
A17: Other health (eg public health, private healthcare, prison healthcare)
... A38: Other (please specify below)
A39: Total | C39: =SUM(C6:C38) -> 0 | D39: =SUM(D6:D38) -> 0 | E39: =SUM(E6:E38) -> 0 | F39: =SUM(F6:F38) -> 0 | G39: =SUM(G6:G38) -> 0 | H39: =SUM(H6:H38) -> 0 | I39: =SUM(I6:I38) -> 0 | J39: =SUM(J6:J38) -> 0 | ... AL39: =SUM(AL6:AL38) -> 0
A41: OPTIONAL FURTHER DATA | C41: If possible, please use the space below to provide a breakdown of the referral sources combined within the 'Other' category above.
A42: =(A1) -> Indicator 1 | C42: Apr-Jun | D42: Jul-Sep | E42: Oct-Dec | F42: Jan-Mar | G42: Apr-Jun | H42: Jul-Sep | I42: Oct-Dec | J42: Jan-Mar | K42: Apr-Jun | L42: Jul-Sep | M42: Oct-Dec | N42: Jan-Mar | O42: Apr-Jun | P42: Jul-Sep | Q42: Oct-Dec | R42: Jan-Mar | S42: Apr-Jun | T42: Jul-Sep | U42: Oct-Dec | V42: Jan-Mar | W42: Apr-Jun | X42: Jul-Sep | Y42: Oct-Dec | Z42: Jan-Mar | AA42: Apr-Jun | AB42: Jul-Sep | AC42: Oct-Dec | AD42: Jan-Mar | AE42: Apr-Jun | AF42: Jul-Sep | AG42: Oct-Dec | AH42: Jan-Mar | AI42: Apr-Jun | AJ42: Jul-Sep | AK42: Oct-Dec | AL42: Jan-Mar
A43: Other (categories and values) | C43: Q1 2023/24 | D43: Q2 2023/24 | E43: Q3 2023/24 | F43: Q4 2023/24 | G43: Q1 2024/25 | H43: Q2 2024/25 | I43: Q3 2024/25 | J43: Q4 2024/25 | K43: Q1 2025/26 | L43: Q2 2025/26 | M43: Q3 2025/26 | N43: Q4 2025/26 | O43: Q1 2026/27 | P43: Q2 2026/27 | Q43: Q3 2026/27 | R43: Q4 2026/27 | S43: Q1 2027/28 | T43: Q2 2027/28 | U43: Q3 2027/28 | V43: Q4 2027/28 | W43: Q1 2028/29 | X43: Q2 2028/29 | Y43: Q3 2028/29 | Z43: Q4 2028/29 | AA43: Q1 2029/30 | AB43: Q2 2029/30 | AC43: Q3 2029/30 | AD43: Q4 2029/30 | AE43: Q1 2030/31 | AF43: Q2 2030/31 | AG43: Q3 2030/31 | AH43: Q4 2030/31 | AI43: Q1 2031/32 | AJ43: Q2 2031/32 | AK43: Q3 2031/32 | AL43: Q4 2031/32
A50: REFLECTIONS AND CAVEATS
A51: Please use the free text field opposite to detail any challenges experienced in completing the above, and where additional clarification or amendments may be needed/helpful.
A53: SUGGESTED PRESENTATION | C53: Proposed charts for reporting template. You may wish to use either or both of the below. We suggest this will be presented alongside a list of the top five referers in your area.
A56: NOTES ON COMPLETION
A57: =(A1) -> Indicator 1 | C57: Counting ASP referrals Whether to count something as an ‘ASP referral’ or not should always be determined by the act of the sender (not the receiver) except in the following two scenarios: ● where a referral is received from a non-professional, such as a concerned member of the public with no knowledge or awareness of ASP and unable to ascertain where to direct their concern OR ● when a welfare concern is escalated to an ASP referral. In the above two exceptions, the status of the referral and whether it should be recorded as an ‘ASP referral’ or not would be determined by a worker and not the original source of the referral. ASP referrals tell us about the number of referrals received, and importantly from which sources they come from to inform training needs and awareness raising activities. They should not be expected to match the number of adults referred to ASP Services or subsequent S4 inquiries. More than one ASP referral can be received for the same individual from different agencies that have come into contact with the adult. This may be for: ● The same individual, same incident, and same type of harm at a singular point in time ● The same individual but separate incidents or different types of harm within a short timescale Such referrals may or may not generate a separate inquiry. This will depend on local practices and whether different ASP referrals for the same individual are linked in systems. Recording the source of the ASP referral This should always be the original source of the referral with the following exception. For welfare concern referrals escalated by a social worker to an ASP referral, the original source of the referral should be recorded. For example, a welfare concern from the police escalated to an ASP referral by a social worker should be counted as an ‘ASP referral’ with ‘police’ recorded as the source of the referral.
A59: DEFINITIONS
A60: ASP Referral | C60: ASP referras are made by different stakeholders to the Health and Social Care Partnership’s (HSCP) Adult Protection Service where it is known or believed that an adult is at risk, and that further action may be required to protect the person’s well-being, property or financial affairs. There is a duty on certain public bodies or office holders who know or believe that a person is an adult at risk of harm and that action may need to be taken to protect them, to make an ASP referral. However, ASP referrals may be received from sources in addition to public bodies, including third sector organisations, members of the public, or the person at risk themselves. Referrers do not need to have evidence that all elements of the three-point criteria, as referred to in the Act, have been met. Good practice would dictate that even if in doubt the referral should be made. This should be counted as an ASP referral by the HSCP’s Adult Protection Service receiving it. Following receipt of an ASP referral, if the council knows or believes that the adult is at risk of harm and that it might need to intervene to protect their wellbeing, property or financial affairs, a S4 inquiry must be undertaken.
A61: ASP Referral source categories | C61: These are standard umbrella categories, reflecting service types. We need something that will work for all 32 Local Authority areas. We appreciate, however, that how services are managed (and what professionals are involved within these services) will be different in different areas. Hence the illustrations provided, are just illustrations, and may not be an exact fit with how things are organised in your particular environment. Please be guided by the service type For example, there are Social Work Occupational Therapists (OTs) as well as NHS OTs. The former would be recorded as a social work referral as it is the service, not the job role, which has key importance here. Similarly, workers with the same job title can work in different service types eg a nurse may work in Primary Care, in Acute Services or in Community Health Services. We appreciate that referrals from integrated teams will be harder to categorise. This will need to be a local decision as to whether there is a broad fit with the categories provided’ or if you feel the need to include under ‘other’ - recording further details and any caveats to highlight data issues going forward. Please remember that where you are using the ‘other category’ that you should provide information specifying the referral source. We will review the use of ‘other’ going forward. Be guided by the reason for collecting the ASP referral source Remember that a key reason for collecting the source of an ASP referral is to help you understand what local services are contributing to ASP work, and to inform and help you target what training or awareness raising is required. To support this, you might want to consider training to ensure the data is captured in a consistent way and takes account of how services are organised in your local area. And, while not a requirement of the Minimum Dataset, you may choose to provide further sub-categories under the umbrella categories we have provided locally.
C62: Health source categories
C63: Category | E63: Description / illustrative example
C64: Healthcare Improvement Scotland
C65: NHS 24
C66: NHS Primary Care | E66: GPs, dentists, pharmacists, optometrists or District Nurses.
C67: NHS Acute Services | E67: General hospitals including maternity hospitals, some other community hospitals specialising in care such as rehab or long-term care may be included here or could be added to the community health category.
C68: NHS Specialist Drug and Alcohol services | E68: This would cover all NHS drug and alcohol services in-patient and community based. Please note that drug and alcohol services are typically led and managed under mental health services in the NHS.
C69: NHS Community Health Services | E69: Health visitors, school nurses, family nurses, midwives, community hospital staff, Allied Health Professionals (rehab, day services etc); possibly district nursing depending on local service arrangements.
C70: Mental Health Services – hospital and community | E70: This would cover all in-patient and community based mental health services including Learning Disability services, CAMHS, Psychiatric Liaison and crisis. Also psychology services — mostly mental health but may include other service areas depending on local arrangements. It may also include GP based mental health practitioners - again, depending on local arrangements.
C71: Other Health | E71: E.g. Public Health, Private Healthcare, Prison Healthcare
C72: Scottish Ambulance Service
...

Sheet 2-3 INQUIRIES
A1: Indicator 2 | C1: INQUIRIES UNDERTAKEN WITHOUT THE USE OF INVESTIGATORY POWERS
A2: Indicator 3 | C2: INQUIRIES UNDERTAKEN WITH THE USE OF INVESTIGATORY POWERS
A4: LOCAL DATA
A5: =A1 -> Indicator 2 | C5: Apr-Jun | D5: Jul-Sep | E5: Oct-Dec | F5: Jan-Mar | G5: Apr-Jun | H5: Jul-Sep | I5: Oct-Dec | J5: Jan-Mar | K5: Apr-Jun | L5: Jul-Sep | M5: Oct-Dec | N5: Jan-Mar | O5: Apr-Jun | P5: Jul-Sep | Q5: Oct-Dec | R5: Jan-Mar | S5: Apr-Jun | T5: Jul-Sep | U5: Oct-Dec | V5: Jan-Mar | W5: Apr-Jun | X5: Jul-Sep | Y5: Oct-Dec | Z5: Jan-Mar | AA5: Apr-Jun | AB5: Jul-Sep | AC5: Oct-Dec | AD5: Jan-Mar | AE5: Apr-Jun | AF5: Jul-Sep | AG5: Oct-Dec | AH5: Jan-Mar | AI5: Apr-Jun | AJ5: Jul-Sep | AK5: Oct-Dec | AL5: Jan-Mar
C6: Q1 2023/24 | D6: Q2 2023/24 | E6: Q3 2023/24 | F6: Q4 2023/24 | G6: Q1 2024/25 | H6: Q2 2024/25 | I6: Q3 2024/25 | J6: Q4 2024/25 | K6: Q1 2025/26 | L6: Q2 2025/26 | M6: Q3 2025/26 | N6: Q4 2025/26 | O6: Q1 2026/27 | P6: Q2 2026/27 | Q6: Q3 2026/27 | R6: Q4 2026/27 | S6: Q1 2027/28 | T6: Q2 2027/28 | U6: Q3 2027/28 | V6: Q4 2027/28 | W6: Q1 2028/29 | X6: Q2 2028/29 | Y6: Q3 2028/29 | Z6: Q4 2028/29 | AA6: Q1 2029/30 | AB6: Q2 2029/30 | AC6: Q3 2029/30 | AD6: Q4 2029/30 | AE6: Q1 2030/31 | AF6: Q2 2030/31 | AG6: Q3 2030/31 | AH6: Q4 2030/31 | AI6: Q1 2031/32 | AJ6: Q2 2031/32 | AK6: Q3 2031/32 | AL6: Q4 2031/32
A7: Total inquiries where investigatory powers are not used
A9: =A2 -> Indicator 3 | C9: Apr-Jun | D9: Jul-Sep | E9: Oct-Dec | F9: Jan-Mar | G9: Apr-Jun | H9: Jul-Sep | I9: Oct-Dec | J9: Jan-Mar | K9: Apr-Jun | L9: Jul-Sep | M9: Oct-Dec | N9: Jan-Mar | O9: Apr-Jun | P9: Jul-Sep | Q9: Oct-Dec | R9: Jan-Mar | S9: Apr-Jun | T9: Jul-Sep | U9: Oct-Dec | V9: Jan-Mar | W9: Apr-Jun | X9: Jul-Sep | Y9: Oct-Dec | Z9: Jan-Mar | AA9: Apr-Jun | AB9: Jul-Sep | AC9: Oct-Dec | AD9: Jan-Mar | AE9: Apr-Jun | AF9: Jul-Sep | AG9: Oct-Dec | AH9: Jan-Mar | AI9: Apr-Jun | AJ9: Jul-Sep | AK9: Oct-Dec | AL9: Jan-Mar
C10: Q1 2023/24 | D10: Q2 2023/24 | E10: Q3 2023/24 | F10: Q4 2023/24 | G10: Q1 2024/25 | H10: Q2 2024/25 | I10: Q3 2024/25 | J10: Q4 2024/25 | K10: Q1 2025/26 | L10: Q2 2025/26 | M10: Q3 2025/26 | N10: Q4 2025/26 | O10: Q1 2026/27 | P10: Q2 2026/27 | Q10: Q3 2026/27 | R10: Q4 2026/27 | S10: Q1 2027/28 | T10: Q2 2027/28 | U10: Q3 2027/28 | V10: Q4 2027/28 | W10: Q1 2028/29 | X10: Q2 2028/29 | Y10: Q3 2028/29 | Z10: Q4 2028/29 | AA10: Q1 2029/30 | AB10: Q2 2029/30 | AC10: Q3 2029/30 | AD10: Q4 2029/30 | AE10: Q1 2030/31 | AF10: Q2 2030/31 | AG10: Q3 2030/31 | AH10: Q4 2030/31 | AI10: Q1 2031/32 | AJ10: Q2 2031/32 | AK10: Q3 2031/32 | AL10: Q4 2031/32
A11: Total inquiries where investigatory powers are used
A13: REFLECTIONS AND CAVEATS
A14: Please use the free text field opposite to detail any challenges experienced in completing the above, and where additional clarification or amendments may be needed/helpful.
A16: SUGGESTED PRESENTATION
A19: HELPER TABLES FOR I2-3 CHARTS
A20: Inquiries as percent of whole | C20: Apr-Jun | D20: Jul-Sep | E20: Oct-Dec | F20: Jan-Mar | G20: Apr-Jun | H20: Jul-Sep | I20: Oct-Dec | J20: Jan-Mar | K20: Apr-Jun | L20: Jul-Sep | M20: Oct-Dec | N20: Jan-Mar | O20: Apr-Jun | P20: Jul-Sep | Q20: Oct-Dec | R20: Jan-Mar | S20: Apr-Jun | T20: Jul-Sep | U20: Oct-Dec | V20: Jan-Mar | W20: Apr-Jun | X20: Jul-Sep | Y20: Oct-Dec | Z20: Jan-Mar | AA20: Apr-Jun | AB20: Jul-Sep | AC20: Oct-Dec | AD20: Jan-Mar | AE20: Apr-Jun | AF20: Jul-Sep | AG20: Oct-Dec | AH20: Jan-Mar | AI20: Apr-Jun | AJ20: Jul-Sep | AK20: Oct-Dec | AL20: Jan-Mar
A21: NOT TO BE USED FOR DATA ENTRY | C21: Q1 2023/24 | D21: Q2 2023/24 | E21: Q3 2023/24 | F21: Q4 2023/24 | G21: Q1 2024/25 | H21: Q2 2024/25 | I21: Q3 2024/25 | J21: Q4 2024/25 | K21: Q1 2025/26 | L21: Q2 2025/26 | M21: Q3 2025/26 | N21: Q4 2025/26 | O21: Q1 2026/27 | P21: Q2 2026/27 | Q21: Q3 2026/27 | R21: Q4 2026/27 | S21: Q1 2027/28 | T21: Q2 2027/28 | U21: Q3 2027/28 | V21: Q4 2027/28 | W21: Q1 2028/29 | X21: Q2 2028/29 | Y21: Q3 2028/29 | Z21: Q4 2028/29 | AA21: Q1 2029/30 | AB21: Q2 2029/30 | AC21: Q3 2029/30 | AD21: Q4 2029/30 | AE21: Q1 2030/31 | AF21: Q2 2030/31 | AG21: Q3 2030/31 | AH21: Q4 2030/31 | AI21: Q1 2031/32 | AJ21: Q2 2031/32 | AK21: Q3 2031/32 | AL21: Q4 2031/32
A22: Total inquiries where investigatory powers are not used (%) | C22: =IFERROR(ROUND(('2-3 INQUIRIES'!C7/'Conversion data'!C7)*100,1),0) -> 0 | D22: =IFERROR(ROUND(('2-3 INQUIRIES'!D7/'Conversion data'!D7)*100,1),0) -> 0 | E22: =IFERROR(ROUND(('2-3 INQUIRIES'!E7/'Conversion data'!E7)*100,1),0) -> 0 | F22: =IFERROR(ROUND(('2-3 INQUIRIES'!F7/'Conversion data'!F7)*100,1),0) -> 0 | G22: =IFERROR(ROUND(('2-3 INQUIRIES'!G7/'Conversion data'!G7)*100,1),0) -> 0 | H22: =IFERROR(ROUND(('2-3 INQUIRIES'!H7/'Conversion data'!H7)*100,1),0) -> 0 | I22: =IFERROR(ROUND(('2-3 INQUIRIES'!I7/'Conversion data'!I7)*100,1),0) -> 0 | J22: =IFERROR(ROUND(('2-3 INQUIRIES'!J7/'Conversion data'!J7)*100,1),0) -> 0 | ... AL22: =IFERROR(ROUND(('2-3 INQUIRIES'!AL7/'Conversion data'!AL7)*100,1),0) -> 0
A23: Total inquiries where investigatory powers are used (%) | C23: =IFERROR(ROUND(('2-3 INQUIRIES'!C11/'Conversion data'!C7)*100,1),0) -> 0 | D23: =IFERROR(ROUND(('2-3 INQUIRIES'!D11/'Conversion data'!D7)*100,1),0) -> 0 | E23: =IFERROR(ROUND(('2-3 INQUIRIES'!E11/'Conversion data'!E7)*100,1),0) -> 0 | F23: =IFERROR(ROUND(('2-3 INQUIRIES'!F11/'Conversion data'!F7)*100,1),0) -> 0 | G23: =IFERROR(ROUND(('2-3 INQUIRIES'!G11/'Conversion data'!G7)*100,1),0) -> 0 | H23: =IFERROR(ROUND(('2-3 INQUIRIES'!H11/'Conversion data'!H7)*100,1),0) -> 0 | I23: =IFERROR(ROUND(('2-3 INQUIRIES'!I11/'Conversion data'!I7)*100,1),0) -> 0 | J23: =IFERROR(ROUND(('2-3 INQUIRIES'!J11/'Conversion data'!J7)*100,1),0) -> 0 | ... AL23: =IFERROR(ROUND(('2-3 INQUIRIES'!AL11/'Conversion data'!AL7)*100,1),0) -> 0
A25: NOTES ON COMPLETION
A26: =(A1&" and "&A2) -> Indicator 2 and Indicator 3 | C26: It is the trigger point of an inquiry that determines what quarter it should be recorded in. This is pertinent to inquiries that conclude without use of investigatory powers, and to inquiries that use investigatory powers. Further notes We do not expect ASP referrals to match the number of inquiries. We know, for example, that multiple agencies can make an ASP referral for the same person- triggered by the same or a different incident. Neither should we equate the number of inquiries with the number of adults being inquired about. For example, a fresh ASP referral may result in a new inquiry being triggered in a quarter, if the previous inquiry has been closed. If it has not been closed, it would be a continuing inquiry with new information. Equally, if an initial case conference is pending or an adult has an ASPP in place, an ASP referral would provide new information, but would not necessarily trigger a new inquiry. We are aware that, in certain areas, some ASP referrals are closed to ASP processes before an S4 inquiry has been undertaken (separate from those circumstances described above). These may be passed/signposted to another team or service in the absence of a S4 inquiry. Guidance and clarification has been requested from the Scottish Government on the general duty to make inquiries under S4 of the Act. Any clarifying or best practice information received will contribute to future minimum dataset guidance regarding these particular indicators.
A28: DEFINITIONS
A29: Inquiries and inquiries using investigatory powers | C29: The purpose of an inquiry, with or without use of investigatory powers, is to ascertain whether adults are at risk of harm, and whether the council may need to intervene, provide support, or any other assistance to the adult or any carer. Any use of investigatory powers is triggered through the S4 duty to inquire under the Act. An inquiry using investigatory powers requires the involvement of a council officer (an individual appointed by a council to perform specific functions under the terms of the Act). It may also require production of a risk assessment if initial inquiries show that further ASP activity is warranted. An inquiry which does not use investigatory powers may or may not require the involvement of a council officer, depending on local arrangements and the nature of the tasks. The collation and consideration of relevant materials, including consideration of previous records relating to the individual and seeking the views of other agencies and professionals, does not necessarily need to be undertaken by a council officer if these inquiries do not include use of investigatory powers. Investigatory powers will be required, and a council officer involved, where there is a need for a visit and direct contact with the adult for interview or medical examination, or for the examination of record (undertaking activity from Sections 7-10 of the Act). Inquiries may involve a single agency or more, as relevant to the case. It should be noted that use of inquiries (with or without use of investigatory powers) supports a move away from talking about inquiries and investigations, and is aligned with the revised Code of Practice (July 2022).
A31: DATE REPORTED
A32: =(A1&" – "&A2) -> Indicator 2 – Indicator 3 | C32: Cumulative number by end of quarter (eg January to March 2023)

Sheet Conversion data
A1: Supplemental | C1: CONVERSION RATES OF REFERRALS TO INQUIRIES
A3: LOCAL DATA
A4: Conversion data | C4: Apr-Jun | D4: Jul-Sep | E4: Oct-Dec | F4: Jan-Mar | G4: Apr-Jun | H4: Jul-Sep | I4: Oct-Dec | J4: Jan-Mar | K4: Apr-Jun | L4: Jul-Sep | M4: Oct-Dec | N4: Jan-Mar | O4: Apr-Jun | P4: Jul-Sep | Q4: Oct-Dec | R4: Jan-Mar | S4: Apr-Jun | T4: Jul-Sep | U4: Oct-Dec | V4: Jan-Mar | W4: Apr-Jun | X4: Jul-Sep | Y4: Oct-Dec | Z4: Jan-Mar | AA4: Apr-Jun | AB4: Jul-Sep | AC4: Oct-Dec | AD4: Jan-Mar | AE4: Apr-Jun | AF4: Jul-Sep | AG4: Oct-Dec | AH4: Jan-Mar | AI4: Apr-Jun | AJ4: Jul-Sep | AK4: Oct-Dec | AL4: Jan-Mar
A5: NOT TO BE USED FOR DATA ENTRY | C5: Q1 2023/24 | D5: Q2 2023/24 | E5: Q3 2023/24 | F5: Q4 2023/24 | G5: Q1 2024/25 | H5: Q2 2024/25 | I5: Q3 2024/25 | J5: Q4 2024/25 | K5: Q1 2025/26 | L5: Q2 2025/26 | M5: Q3 2025/26 | N5: Q4 2025/26 | O5: Q1 2026/27 | P5: Q2 2026/27 | Q5: Q3 2026/27 | R5: Q4 2026/27 | S5: Q1 2027/28 | T5: Q2 2027/28 | U5: Q3 2027/28 | V5: Q4 2027/28 | W5: Q1 2028/29 | X5: Q2 2028/29 | Y5: Q3 2028/29 | Z5: Q4 2028/29 | AA5: Q1 2029/30 | AB5: Q2 2029/30 | AC5: Q3 2029/30 | AD5: Q4 2029/30 | AE5: Q1 2030/31 | AF5: Q2 2030/31 | AG5: Q3 2030/31 | AH5: Q4 2030/31 | AI5: Q1 2031/32 | AJ5: Q2 2031/32 | AK5: Q3 2031/32 | AL5: Q4 2031/32
A6: Total referrals | C6: ='1 ASP REFERRALS'!C39 -> 0 | D6: ='1 ASP REFERRALS'!D39 -> 0 | E6: ='1 ASP REFERRALS'!E39 -> 0 | F6: ='1 ASP REFERRALS'!F39 -> 0 | G6: ='1 ASP REFERRALS'!G39 -> 0 | H6: ='1 ASP REFERRALS'!H39 -> 0 | I6: ='1 ASP REFERRALS'!I39 -> 0 | J6: ='1 ASP REFERRALS'!J39 -> 0 | ... AL6: ='1 ASP REFERRALS'!AL39 -> 0
A7: Total inquiries | C7: =SUM('2-3 INQUIRIES'!C7+'2-3 INQUIRIES'!C11) -> 0 | D7: =SUM('2-3 INQUIRIES'!D7+'2-3 INQUIRIES'!D11) -> 0 | E7: =SUM('2-3 INQUIRIES'!E7+'2-3 INQUIRIES'!E11) -> 0 | F7: =SUM('2-3 INQUIRIES'!F7+'2-3 INQUIRIES'!F11) -> 0 | G7: =SUM('2-3 INQUIRIES'!G7+'2-3 INQUIRIES'!G11) -> 0 | H7: =SUM('2-3 INQUIRIES'!H7+'2-3 INQUIRIES'!H11) -> 0 | I7: =SUM('2-3 INQUIRIES'!I7+'2-3 INQUIRIES'!I11) -> 0 | J7: =SUM('2-3 INQUIRIES'!J7+'2-3 INQUIRIES'!J11) -> 0 | ... AL7: =SUM('2-3 INQUIRIES'!AL7+'2-3 INQUIRIES'!AL11) -> 0
A8: Conversion rate (%) | C8: =IFERROR(ROUND((C7/C6)*100,1),0) -> 0 | D8: =IFERROR(ROUND((D7/D6)*100,1),0) -> 0 | E8: =IFERROR(ROUND((E7/E6)*100,1),0) -> 0 | F8: =IFERROR(ROUND((F7/F6)*100,1),0) -> 0 | G8: =IFERROR(ROUND((G7/G6)*100,1),0) -> 0 | H8: =IFERROR(ROUND((H7/H6)*100,1),0) -> 0 | I8: =IFERROR(ROUND((I7/I6)*100,1),0) -> 0 | J8: =IFERROR(ROUND((J7/J6)*100,1),0) -> 0 | ... AL8: =IFERROR(ROUND((AL7/AL6)*100,1),0) -> 0
A9: ='2-3 INQUIRIES'!A7 -> Total inquiries where investigatory powers are not used | C9: ='2-3 INQUIRIES'!C7 -> 0 | D9: ='2-3 INQUIRIES'!D7 -> 0 | E9: ='2-3 INQUIRIES'!E7 -> 0 | F9: ='2-3 INQUIRIES'!F7 -> 0 | G9: ='2-3 INQUIRIES'!G7 -> 0 | H9: ='2-3 INQUIRIES'!H7 -> 0 | I9: ='2-3 INQUIRIES'!I7 -> 0 | J9: ='2-3 INQUIRIES'!J7 -> 0 | ... AL9: ='2-3 INQUIRIES'!AL7 -> 0
A10: ='2-3 INQUIRIES'!A11 -> Total inquiries where investigatory powers are used | C10: ='2-3 INQUIRIES'!C11 -> 0 | D10: ='2-3 INQUIRIES'!D11 -> 0 | E10: ='2-3 INQUIRIES'!E11 -> 0 | F10: ='2-3 INQUIRIES'!F11 -> 0 | G10: ='2-3 INQUIRIES'!G11 -> 0 | H10: ='2-3 INQUIRIES'!H11 -> 0 | I10: ='2-3 INQUIRIES'!I11 -> 0 | J10: ='2-3 INQUIRIES'!J11 -> 0 | ... AL10: ='2-3 INQUIRIES'!AL11 -> 0
A11: =A8 & " " & A9 -> Conversion rate (%) Total inquiries where investigatory powers are not used | C11: =IFERROR(ROUND((C9/C6)*100,1),0) -> 0 | D11: =IFERROR(ROUND((D9/D6)*100,1),0) -> 0 | E11: =IFERROR(ROUND((E9/E6)*100,1),0) -> 0 | F11: =IFERROR(ROUND((F9/F6)*100,1),0) -> 0 | G11: =IFERROR(ROUND((G9/G6)*100,1),0) -> 0 | H11: =IFERROR(ROUND((H9/H6)*100,1),0) -> 0 | I11: =IFERROR(ROUND((I9/I6)*100,1),0) -> 0 | J11: =IFERROR(ROUND((J9/J6)*100,1),0) -> 0 | ... AL11: =IFERROR(ROUND((AL9/AL6)*100,1),0) -> 0
A12: =A8 & " " & A10 -> Conversion rate (%) Total inquiries where investigatory powers are used | C12: =IFERROR(ROUND((C10/C6)*100,1),0) -> 0 | D12: =IFERROR(ROUND((D10/D6)*100,1),0) -> 0 | E12: =IFERROR(ROUND((E10/E6)*100,1),0) -> 0 | F12: =IFERROR(ROUND((F10/F6)*100,1),0) -> 0 | G12: =IFERROR(ROUND((G10/G6)*100,1),0) -> 0 | H12: =IFERROR(ROUND((H10/H6)*100,1),0) -> 0 | I12: =IFERROR(ROUND((I10/I6)*100,1),0) -> 0 | J12: =IFERROR(ROUND((J10/J6)*100,1),0) -> 0 | ... AL12: =IFERROR(ROUND((AL10/AL6)*100,1),0) -> 0
A14: SUGGESTED PRESENTATION

Sheet 4 CCs
A1: Indicator 4a | C1: INITIAL CASE CONFERENCES
A2: Indicator 4b | C2: REVIEW CASE CONFERENCES
A4: LOCAL DATA
A5: =(A1&" - "&A2) -> Indicator 4a - Indicator 4b | C5: Apr-Jun | D5: Jul-Sep | E5: Oct-Dec | F5: Jan-Mar | G5: Apr-Jun | H5: Jul-Sep | I5: Oct-Dec | J5: Jan-Mar | K5: Apr-Jun | L5: Jul-Sep | M5: Oct-Dec | N5: Jan-Mar | O5: Apr-Jun | P5: Jul-Sep | Q5: Oct-Dec | R5: Jan-Mar | S5: Apr-Jun | T5: Jul-Sep | U5: Oct-Dec | V5: Jan-Mar | W5: Apr-Jun | X5: Jul-Sep | Y5: Oct-Dec | Z5: Jan-Mar | AA5: Apr-Jun | AB5: Jul-Sep | AC5: Oct-Dec | AD5: Jan-Mar | AE5: Apr-Jun | AF5: Jul-Sep | AG5: Oct-Dec | AH5: Jan-Mar | AI5: Apr-Jun | AJ5: Jul-Sep | AK5: Oct-Dec | AL5: Jan-Mar
C6: Q1 2023/24 | D6: Q2 2023/24 | E6: Q3 2023/24 | F6: Q4 2023/24 | G6: Q1 2024/25 | H6: Q2 2024/25 | I6: Q3 2024/25 | J6: Q4 2024/25 | K6: Q1 2025/26 | L6: Q2 2025/26 | M6: Q3 2025/26 | N6: Q4 2025/26 | O6: Q1 2026/27 | P6: Q2 2026/27 | Q6: Q3 2026/27 | R6: Q4 2026/27 | S6: Q1 2027/28 | T6: Q2 2027/28 | U6: Q3 2027/28 | V6: Q4 2027/28 | W6: Q1 2028/29 | X6: Q2 2028/29 | Y6: Q3 2028/29 | Z6: Q4 2028/29 | AA6: Q1 2029/30 | AB6: Q2 2029/30 | AC6: Q3 2029/30 | AD6: Q4 2029/30 | AE6: Q1 2030/31 | AF6: Q2 2030/31 | AG6: Q3 2030/31 | AH6: Q4 2030/31 | AI6: Q1 2031/32 | AJ6: Q2 2031/32 | AK6: Q3 2031/32 | AL6: Q4 2031/32
A7: Number of initial case conferences
A8: Number of review case conferences
A9: Total | C9: =SUM(C7:C8) -> 0 | D9: =SUM(D7:D8) -> 0 | E9: =SUM(E7:E8) -> 0 | F9: =SUM(F7:F8) -> 0 | G9: =SUM(G7:G8) -> 0 | H9: =SUM(H7:H8) -> 0 | I9: =SUM(I7:I8) -> 0 | J9: =SUM(J7:J8) -> 0 | ... AL9: =SUM(AL7:AL8) -> 0
A11: REFLECTIONS AND CAVEATS
A12: Please use the free text field opposite to detail any challenges experienced in completing the above, and where additional clarification or amendments may be needed/helpful.
A15: SUGGESTED PRESENTATION
A18: NOTES ON COMPLETION
A19: =(A1&" – "&A2) -> Indicator 4a – Indicator 4b
A21: DEFINITIONS
A22: Case conferences
A24: DATE REPORTED
A25: =(A1&" – "&A2) -> Indicator 4a – Indicator 4b | C25: Cumulative number by end of quarter (eg January to March 2023)
A27: RATIONALE
A28: =(A1) -> Indicator 4a | C28: Tells us about levels of activity and resource demands on workforce; indicator on numbers of 'adults at risk' where further action is anticipated.
A29: =(A2) -> Indicator 4b | C29: Tells us about levels of activity and resource demands on workforce; tells us about due diligence in managing and monitoring individual cases.

Sheet 5-7 CC ATTENDEES
A1: Indicator 5a | C1: ADULTS AT RISK INVITED TO ATTEND A CASE CONFERENCE (TOTAL)
A2: Indicator 5b | C2: ADULTS AT RISK INVITED TO ATTEND A CASE CONFERENCE (PERCENTAGE UPTAKE)
A3: Indicator 6a | C3: INDEPENDENT ADVOCATES INVITED TO ATTEND A CASE CONFERENCE (TOTAL)
A4: Indicator 6b | C4: INDEPENDENT ADVOCATES INVITED TO ATTEND A CASE CONFERENCE (PERCENTAGE UPTAKE)
A6: LOCAL DATA
A7: =(A1&" - "&A2) -> Indicator 5a - Indicator 5b | C7: Apr-Jun | D7: Jul-Sep | E7: Oct-Dec | F7: Jan-Mar | G7: Apr-Jun | H7: Jul-Sep | I7: Oct-Dec | J7: Jan-Mar | K7: Apr-Jun | L7: Jul-Sep | M7: Oct-Dec | N7: Jan-Mar | O7: Apr-Jun | P7: Jul-Sep | Q7: Oct-Dec | R7: Jan-Mar | S7: Apr-Jun | T7: Jul-Sep | U7: Oct-Dec | V7: Jan-Mar | W7: Apr-Jun | X7: Jul-Sep | Y7: Oct-Dec | Z7: Jan-Mar | AA7: Apr-Jun | AB7: Jul-Sep | AC7: Oct-Dec | AD7: Jan-Mar | AE7: Apr-Jun | AF7: Jul-Sep | AG7: Oct-Dec | AH7: Jan-Mar | AI7: Apr-Jun | AJ7: Jul-Sep | AK7: Oct-Dec | AL7: Jan-Mar
C8: Q1 2023/24 | D8: Q2 2023/24 | E8: Q3 2023/24 | F8: Q4 2023/24 | G8: Q1 2024/25 | H8: Q2 2024/25 | I8: Q3 2024/25 | J8: Q4 2024/25 | K8: Q1 2025/26 | L8: Q2 2025/26 | M8: Q3 2025/26 | N8: Q4 2025/26 | O8: Q1 2026/27 | P8: Q2 2026/27 | Q8: Q3 2026/27 | R8: Q4 2026/27 | S8: Q1 2027/28 | T8: Q2 2027/28 | U8: Q3 2027/28 | V8: Q4 2027/28 | W8: Q1 2028/29 | X8: Q2 2028/29 | Y8: Q3 2028/29 | Z8: Q4 2028/29 | AA8: Q1 2029/30 | AB8: Q2 2029/30 | AC8: Q3 2029/30 | AD8: Q4 2029/30 | AE8: Q1 2030/31 | AF8: Q2 2030/31 | AG8: Q3 2030/31 | AH8: Q4 2030/31 | AI8: Q1 2031/32 | AJ8: Q2 2031/32 | AK8: Q3 2031/32 | AL8: Q4 2031/32
A9: Adults at risk invited to attend a case conference (total)
A10: Adults at risk invited to attend a case conference (percentage uptake)
A12: =(A3&" - "&A4) -> Indicator 6a - Indicator 6b | C12: Apr-Jun | D12: Jul-Sep | E12: Oct-Dec | F12: Jan-Mar | G12: Apr-Jun | H12: Jul-Sep | I12: Oct-Dec | J12: Jan-Mar | K12: Apr-Jun | L12: Jul-Sep | M12: Oct-Dec | N12: Jan-Mar | O12: Apr-Jun | P12: Jul-Sep | Q12: Oct-Dec | R12: Jan-Mar | S12: Apr-Jun | T12: Jul-Sep | U12: Oct-Dec | V12: Jan-Mar | W12: Apr-Jun | X12: Jul-Sep | Y12: Oct-Dec | Z12: Jan-Mar | AA12: Apr-Jun | AB12: Jul-Sep | AC12: Oct-Dec | AD12: Jan-Mar | AE12: Apr-Jun | AF12: Jul-Sep | AG12: Oct-Dec | AH12: Jan-Mar | AI12: Apr-Jun | AJ12: Jul-Sep | AK12: Oct-Dec | AL12: Jan-Mar
C13: Q1 2023/24 | D13: Q2 2023/24 | E13: Q3 2023/24 | F13: Q4 2023/24 | G13: Q1 2024/25 | H13: Q2 2024/25 | I13: Q3 2024/25 | J13: Q4 2024/25 | K13: Q1 2025/26 | L13: Q2 2025/26 | M13: Q3 2025/26 | N13: Q4 2025/26 | O13: Q1 2026/27 | P13: Q2 2026/27 | Q13: Q3 2026/27 | R13: Q4 2026/27 | S13: Q1 2027/28 | T13: Q2 2027/28 | U13: Q3 2027/28 | V13: Q4 2027/28 | W13: Q1 2028/29 | X13: Q2 2028/29 | Y13: Q3 2028/29 | Z13: Q4 2028/29 | AA13: Q1 2029/30 | AB13: Q2 2029/30 | AC13: Q3 2029/30 | AD13: Q4 2029/30 | AE13: Q1 2030/31 | AF13: Q2 2030/31 | AG13: Q3 2030/31 | AH13: Q4 2030/31 | AI13: Q1 2031/32 | AJ13: Q2 2031/32 | AK13: Q3 2031/32 | AL13: Q4 2031/32
A14: Number of case conferences where an independent advocate has been invited (total)
A15: Uptake of invitations to attend a case conference by independent advocate (percentage)
A17: REFLECTIONS AND CAVEATS
A18: Please use the free text field opposite to detail any challenges experienced in completing the above, and where additional clarification or amendments may be needed/helpful.
A20: SUGGESTED PRESENTATION
A22: HELPER TABLES FOR I.5-6 CHARTS
A23: Indicator 5a - Indicator 5b | C23: Apr-Jun | D23: Jul-Sep | E23: Oct-Dec | F23: Jan-Mar | G23: Apr-Jun | H23: Jul-Sep | I23: Oct-Dec | J23: Jan-Mar | K23: Apr-Jun | L23: Jul-Sep | M23: Oct-Dec | N23: Jan-Mar | O23: Apr-Jun | P23: Jul-Sep | Q23: Oct-Dec | R23: Jan-Mar | S23: Apr-Jun | T23: Jul-Sep | U23: Oct-Dec | V23: Jan-Mar | W23: Apr-Jun | X23: Jul-Sep | Y23: Oct-Dec | Z23: Jan-Mar | AA23: Apr-Jun | AB23: Jul-Sep | AC23: Oct-Dec | AD23: Jan-Mar | AE23: Apr-Jun | AF23: Jul-Sep | AG23: Oct-Dec | AH23: Jan-Mar | AI23: Apr-Jun | AJ23: Jul-Sep | AK23: Oct-Dec | AL23: Jan-Mar
A24: NOT TO BE USED FOR DATA ENTRY | C24: Q1 2023/24 | D24: Q2 2023/24 | E24: Q3 2023/24 | F24: Q4 2023/24 | G24: Q1 2024/25 | H24: Q2 2024/25 | I24: Q3 2024/25 | J24: Q4 2024/25 | K24: Q1 2025/26 | L24: Q2 2025/26 | M24: Q3 2025/26 | N24: Q4 2025/26 | O24: Q1 2026/27 | P24: Q2 2026/27 | Q24: Q3 2026/27 | R24: Q4 2026/27 | S24: Q1 2027/28 | T24: Q2 2027/28 | U24: Q3 2027/28 | V24: Q4 2027/28 | W24: Q1 2028/29 | X24: Q2 2028/29 | Y24: Q3 2028/29 | Z24: Q4 2028/29 | AA24: Q1 2029/30 | AB24: Q2 2029/30 | AC24: Q3 2029/30 | AD24: Q4 2029/30 | AE24: Q1 2030/31 | AF24: Q2 2030/31 | AG24: Q3 2030/31 | AH24: Q4 2030/31 | AI24: Q1 2031/32 | AJ24: Q2 2031/32 | AK24: Q3 2031/32 | AL24: Q4 2031/32
A25: Number of adults who did attend | C25: =IFERROR(ROUND('5-7 CC ATTENDEES'!C9*('5-7 CC ATTENDEES'!C10/100),1),0) -> 0 | D25: =IFERROR(ROUND('5-7 CC ATTENDEES'!D9*('5-7 CC ATTENDEES'!D10/100),1),0) -> 0 | E25: =IFERROR(ROUND('5-7 CC ATTENDEES'!E9*('5-7 CC ATTENDEES'!E10/100),1),0) -> 0 | F25: =IFERROR(ROUND('5-7 CC ATTENDEES'!F9*('5-7 CC ATTENDEES'!F10/100),1),0) -> 0 | G25: =IFERROR(ROUND('5-7 CC ATTENDEES'!G9*('5-7 CC ATTENDEES'!G10/100),1),0) -> 0 | H25: =IFERROR(ROUND('5-7 CC ATTENDEES'!H9*('5-7 CC ATTENDEES'!H10/100),1),0) -> 0 | I25: =IFERROR(ROUND('5-7 CC ATTENDEES'!I9*('5-7 CC ATTENDEES'!I10/100),1),0) -> 0 | J25: =IFERROR(ROUND('5-7 CC ATTENDEES'!J9*('5-7 CC ATTENDEES'!J10/100),1),0) -> 0 | ... AL25: =IFERROR(ROUND('5-7 CC ATTENDEES'!AL9*('5-7 CC ATTENDEES'!AL10/100),1),0) -> 0
A26: Indicator 6a - Indicator 6b | C26: Apr-Jun | D26: Jul-Sep | E26: Oct-Dec | F26: Jan-Mar | G26: Apr-Jun | H26: Jul-Sep | I26: Oct-Dec | J26: Jan-Mar | K26: Apr-Jun | L26: Jul-Sep | M26: Oct-Dec | N26: Jan-Mar | O26: Apr-Jun | P26: Jul-Sep | Q26: Oct-Dec | R26: Jan-Mar | S26: Apr-Jun | T26: Jul-Sep | U26: Oct-Dec | V26: Jan-Mar | W26: Apr-Jun | X26: Jul-Sep | Y26: Oct-Dec | Z26: Jan-Mar | AA26: Apr-Jun | AB26: Jul-Sep | AC26: Oct-Dec | AD26: Jan-Mar | AE26: Apr-Jun | AF26: Jul-Sep | AG26: Oct-Dec | AH26: Jan-Mar | AI26: Apr-Jun | AJ26: Jul-Sep | AK26: Oct-Dec | AL26: Jan-Mar
A27: NOT TO BE USED FOR DATA ENTRY | C27: Q1 2023/24 | D27: Q2 2023/24 | E27: Q3 2023/24 | F27: Q4 2023/24 | G27: Q1 2024/25 | H27: Q2 2024/25 | I27: Q3 2024/25 | J27: Q4 2024/25 | K27: Q1 2025/26 | L27: Q2 2025/26 | M27: Q3 2025/26 | N27: Q4 2025/26 | O27: Q1 2026/27 | P27: Q2 2026/27 | Q27: Q3 2026/27 | R27: Q4 2026/27 | S27: Q1 2027/28 | T27: Q2 2027/28 | U27: Q3 2027/28 | V27: Q4 2027/28 | W27: Q1 2028/29 | X27: Q2 2028/29 | Y27: Q3 2028/29 | Z27: Q4 2028/29 | AA27: Q1 2029/30 | AB27: Q2 2029/30 | AC27: Q3 2029/30 | AD27: Q4 2029/30 | AE27: Q1 2030/31 | AF27: Q2 2030/31 | AG27: Q3 2030/31 | AH27: Q4 2030/31 | AI27: Q1 2031/32 | AJ27: Q2 2031/32 | AK27: Q3 2031/32 | AL27: Q4 2031/32
A28: Number of independent advocates who did attend | C28: =IFERROR(ROUND('5-7 CC ATTENDEES'!C14*('5-7 CC ATTENDEES'!C15/100),1),0) -> 0 | D28: =IFERROR(ROUND('5-7 CC ATTENDEES'!D14*('5-7 CC ATTENDEES'!D15/100),1),0) -> 0 | E28: =IFERROR(ROUND('5-7 CC ATTENDEES'!E14*('5-7 CC ATTENDEES'!E15/100),1),0) -> 0 | F28: =IFERROR(ROUND('5-7 CC ATTENDEES'!F14*('5-7 CC ATTENDEES'!F15/100),1),0) -> 0 | G28: =IFERROR(ROUND('5-7 CC ATTENDEES'!G14*('5-7 CC ATTENDEES'!G15/100),1),0) -> 0 | H28: =IFERROR(ROUND('5-7 CC ATTENDEES'!H14*('5-7 CC ATTENDEES'!H15/100),1),0) -> 0 | I28: =IFERROR(ROUND('5-7 CC ATTENDEES'!I14*('5-7 CC ATTENDEES'!I15/100),1),0) -> 0 | J28: =IFERROR(ROUND('5-7 CC ATTENDEES'!J14*('5-7 CC ATTENDEES'!J15/100),1),0) -> 0 | ... AL28: =IFERROR(ROUND('5-7 CC ATTENDEES'!AL14*('5-7 CC ATTENDEES'!AL15/100),1),0) -> 0
A30: NOTES ON COMPLETION
A31: =(A2&" and "&A4) -> Indicator 5b and Indicator 6b | C31: The percentage of those invited to attend a case conference who took up the offer. Please DO NOT add percentage symbol (%) after the value — it should be inserted automatically.
A32: Indicators 6a & 6b | C32: If more than one independent advocate was ever invited to attend on behalf of the adult at risk, this should be recorded as a single count.
A34: DEFINITIONS
A35: Case conferences | C35: The purpose of case conferences will be defined by local procedures but should include: the sharing of information relating to possible harm; the joint assessment of current and ongoing risk; agreement of a specific and detailed Support and Protection Plan (where required) with timescales for addressing risks and providing services to support and protect the adult. They are sometimes referred to as ‘initial’ and ‘review’ case conferences. Case conferences should be as inclusive of multi-agencies as relevant. There is a presumption that the adult themselves will be in attendance (unless it is considered not to be in their best interests) or the adult freely chooses not to attend with no undue pressure from others. It will consider actions that may need to be taken under the Adult protection legislation, but may also explore options for protecting people under other legislation - including (but not restricted to) provisions under the Mental Health (Care and Treatment) (Scotland) Act 2003 and the Adults with Incapacity (Scotland) Act 2000.
A36: Independent advocate | C36: An independent advocate is provided by a professional service, and cannot be provided by a friend or carer.
A38: DATE REPORTED
A39: =(A1&" – "&A4) -> Indicator 5a – Indicator 6b | C39: Cumulative number by end of quarter (eg January to March 2023)
A41: RATIONALE
A42: =(A1&" – "&A2) -> Indicator 5a – Indicator 5b | C42: Tells us where the 'adult at risk' has been involved, as a contributory factor to their views being taken into account.
A43: =(A3&" – "&A4) -> Indicator 6a – Indicator 6b | C43: Indicates that were are meeting our duty to consider advocacy after the decision has been made to intervene, contributing to the views of the adult being taken into account. Further notes Under the ASPA (2007), there is a duty to consider the provision of advocacy and other services after a decision has been made to intervene (S6). This is for an independent advocate to support the adult at risk to ‘participate as fully as possible’ in understanding, assessing and managing risk and to ensure that the adult’s views and wishes are central. Supported decision-making processes and principles should be considered. This is connected to the duty to balance the need for intervention with the adult’s wishes and right to live as independently as possible, and ensuing actions to ensure that they are safe, protected, supported, involved and consulted. There is not an absolute right to independent advocacy in all cases, as the practitioner has to consider whether or not it is helpful to the adult. However, in cases where the adult has a diagnosed mental health condition, independent advocacy must be offered. Where advocacy is offered, but declined by the adult or not deemed appropriate, it is good practice that the reasons for this should be clearly recorded, as should the reasons for not referring to any other ‘appropriate’ services. This decision should be re-visited and recorded at each formal review e.g. multi-agency meetings, reviews or professional meetings.

Sheet 8-9 ASPPs & POWERS
A1: Indicator 8a | C1: NUMBER OF ADULTS ON ASPPs IN TOTAL AT END OF QUARTER
A2: Indicator 8b | C2: NUMBER OF ADULTS WITH NEWLY COMMENCED ASPPs WITHIN QUARTER ONLY
A3: Indicator 9a | C3: PROTECTION ORDERS (APPLIED FOR)
A4: Indicator 9b | C4: PROTECTION ORDERS (GRANTED)
A6: LOCAL DATA
A7: =(A1&" - "&A2) -> Indicator 8a - Indicator 8b | C7: Apr-Jun | D7: Jul-Sep | E7: Oct-Dec | F7: Jan-Mar | G7: Apr-Jun | H7: Jul-Sep | I7: Oct-Dec | J7: Jan-Mar | K7: Apr-Jun | L7: Jul-Sep | M7: Oct-Dec | N7: Jan-Mar | O7: Apr-Jun | P7: Jul-Sep | Q7: Oct-Dec | R7: Jan-Mar | S7: Apr-Jun | T7: Jul-Sep | U7: Oct-Dec | V7: Jan-Mar | W7: Apr-Jun | X7: Jul-Sep | Y7: Oct-Dec | Z7: Jan-Mar | AA7: Apr-Jun | AB7: Jul-Sep | AC7: Oct-Dec | AD7: Jan-Mar | AE7: Apr-Jun | AF7: Jul-Sep | AG7: Oct-Dec | AH7: Jan-Mar | AI7: Apr-Jun | AJ7: Jul-Sep | AK7: Oct-Dec | AL7: Jan-Mar
C8: Q1 2023/24 | D8: Q2 2023/24 | E8: Q3 2023/24 | F8: Q4 2023/24 | G8: Q1 2024/25 | H8: Q2 2024/25 | I8: Q3 2024/25 | J8: Q4 2024/25 | K8: Q1 2025/26 | L8: Q2 2025/26 | M8: Q3 2025/26 | N8: Q4 2025/26 | O8: Q1 2026/27 | P8: Q2 2026/27 | Q8: Q3 2026/27 | R8: Q4 2026/27 | S8: Q1 2027/28 | T8: Q2 2027/28 | U8: Q3 2027/28 | V8: Q4 2027/28 | W8: Q1 2028/29 | X8: Q2 2028/29 | Y8: Q3 2028/29 | Z8: Q4 2028/29 | AA8: Q1 2029/30 | AB8: Q2 2029/30 | AC8: Q3 2029/30 | AD8: Q4 2029/30 | AE8: Q1 2030/31 | AF8: Q2 2030/31 | AG8: Q3 2030/31 | AH8: Q4 2030/31 | AI8: Q1 2031/32 | AJ8: Q2 2031/32 | AK8: Q3 2031/32 | AL8: Q4 2031/32
A9: Total number of managed ASPPs
A10: Total number of newly commenced ASPPs
A12: =A3 -> Indicator 9a | C12: Apr-Jun | D12: Jul-Sep | E12: Oct-Dec | F12: Jan-Mar | G12: Apr-Jun | H12: Jul-Sep | I12: Oct-Dec | J12: Jan-Mar | K12: Apr-Jun | L12: Jul-Sep | M12: Oct-Dec | N12: Jan-Mar | O12: Apr-Jun | P12: Jul-Sep | Q12: Oct-Dec | R12: Jan-Mar | S12: Apr-Jun | T12: Jul-Sep | U12: Oct-Dec | V12: Jan-Mar | W12: Apr-Jun | X12: Jul-Sep | Y12: Oct-Dec | Z12: Jan-Mar | AA12: Apr-Jun | AB12: Jul-Sep | AC12: Oct-Dec | AD12: Jan-Mar | AE12: Apr-Jun | AF12: Jul-Sep | AG12: Oct-Dec | AH12: Jan-Mar | AI12: Apr-Jun | AJ12: Jul-Sep | AK12: Oct-Dec | AL12: Jan-Mar
C13: Q1 2023/24 | D13: Q2 2023/24 | E13: Q3 2023/24 | F13: Q4 2023/24 | G13: Q1 2024/25 | H13: Q2 2024/25 | I13: Q3 2024/25 | J13: Q4 2024/25 | K13: Q1 2025/26 | L13: Q2 2025/26 | M13: Q3 2025/26 | N13: Q4 2025/26 | O13: Q1 2026/27 | P13: Q2 2026/27 | Q13: Q3 2026/27 | R13: Q4 2026/27 | S13: Q1 2027/28 | T13: Q2 2027/28 | U13: Q3 2027/28 | V13: Q4 2027/28 | W13: Q1 2028/29 | X13: Q2 2028/29 | Y13: Q3 2028/29 | Z13: Q4 2028/29 | AA13: Q1 2029/30 | AB13: Q2 2029/30 | AC13: Q3 2029/30 | AD13: Q4 2029/30 | AE13: Q1 2030/31 | AF13: Q2 2030/31 | AG13: Q3 2030/31 | AH13: Q4 2030/31 | AI13: Q1 2031/32 | AJ13: Q2 2031/32 | AK13: Q3 2031/32 | AL13: Q4 2031/32
A14: Assessment orders
A15: Removal orders
A16: Banning or temporary banning orders
A18: =A4 -> Indicator 9b | C18: Apr-Jun | D18: Jul-Sep | E18: Oct-Dec | F18: Jan-Mar | G18: Apr-Jun | H18: Jul-Sep | I18: Oct-Dec | J18: Jan-Mar | K18: Apr-Jun | L18: Jul-Sep | M18: Oct-Dec | N18: Jan-Mar | O18: Apr-Jun | P18: Jul-Sep | Q18: Oct-Dec | R18: Jan-Mar | S18: Apr-Jun | T18: Jul-Sep | U18: Oct-Dec | V18: Jan-Mar | W18: Apr-Jun | X18: Jul-Sep | Y18: Oct-Dec | Z18: Jan-Mar | AA18: Apr-Jun | AB18: Jul-Sep | AC18: Oct-Dec | AD18: Jan-Mar | AE18: Apr-Jun | AF18: Jul-Sep | AG18: Oct-Dec | AH18: Jan-Mar | AI18: Apr-Jun | AJ18: Jul-Sep | AK18: Oct-Dec | AL18: Jan-Mar
C19: Q1 2023/24 | D19: Q2 2023/24 | E19: Q3 2023/24 | F19: Q4 2023/24 | G19: Q1 2024/25 | H19: Q2 2024/25 | I19: Q3 2024/25 | J19: Q4 2024/25 | K19: Q1 2025/26 | L19: Q2 2025/26 | M19: Q3 2025/26 | N19: Q4 2025/26 | O19: Q1 2026/27 | P19: Q2 2026/27 | Q19: Q3 2026/27 | R19: Q4 2026/27 | S19: Q1 2027/28 | T19: Q2 2027/28 | U19: Q3 2027/28 | V19: Q4 2027/28 | W19: Q1 2028/29 | X19: Q2 2028/29 | Y19: Q3 2028/29 | Z19: Q4 2028/29 | AA19: Q1 2029/30 | AB19: Q2 2029/30 | AC19: Q3 2029/30 | AD19: Q4 2029/30 | AE19: Q1 2030/31 | AF19: Q2 2030/31 | AG19: Q3 2030/31 | AH19: Q4 2030/31 | AI19: Q1 2031/32 | AJ19: Q2 2031/32 | AK19: Q3 2031/32 | AL19: Q4 2031/32
A20: Assessment orders
A21: Removal orders
A22: Banning or temporary banning orders
A24: REFLECTIONS AND CAVEATS
A25: Please use the free text field opposite to detail any challenges experienced in completing the above, and where additional clarification or amendments may be needed/helpful.
A27: SUGGESTED PRESENTATION
A31: NOTES ON COMPLETION
A32: =A1 -> Indicator 8a | C32: Total number of adults on open plans under ASP at the end of a quarter. Please note, an ASPP is closed when there is no longer any ASP oversight of support actions.
A33: =A2 -> Indicator 8b | C33: Total newly commenced ASPPs are those started in a quarter and exclude review plans. An ASPP revised at a review Case Conference is NOT a new ASPP.
A35: DEFINITIONS
A36: Adult Support and Protection Plans (ASPPs) | C36: An Adult Support and Protection Plan is a set of actions and strategies agreed by relevant agencies (single or multi-agency) and put in place to support and protect ‘adults at risk’ meeting the three-point criteria. The Plan is designed to eliminate or reduce risk, manage this over time and respond to changing circumstances, overseen through case conference processes. Plans will stay in place until agreed that they are no longer necessary. Adult Support and Protection Plans should be agreed across all relevant agencies identifying who is responsible for which aspects of the plan, the anticipated timetable, and reporting arrangements. This should include a date for a review meeting - unless it has been agreed that no further actions are required under the terms of the Act. It is also expected that the adult should be supported to contribute to the fullest possible extent and understand the actions in the said Plan. An Adult Protection Plan can be initiated at any point of the ASP process depending on need or urgency or local processes, but most commonly at a case conference.
A37: Protection orders | C37: The Act allows for application to a sheriff for a Protection Order. Applications must be made by the council, save for banning orders. Here, the application may also be made by or on behalf of the adult whose well-being or property would be safeguarded by the order, or any other person who is entitled to occupy the place concerned. Protection Orders may be applied for at any time. Applications can be made for another Protection Order, but not until the expiry date of the one in place. Assessment Orders An order granted by a sheriff to help the council decide whether the person is an adult at risk and, if so, whether it needs to do anything to protect the person from harm. These may be to carry out an interview or medical examination of a person and are valid for 7 days. Removal Orders An order granted by a sheriff to remove an adult at risk to a specified place to assess and protect them, effective for a maximum of 7 days after the day on which the person is removed, which must take place within 72 hours of the order being granted. Banning/Temporary Banning Orders An order granted by a sheriff to ban the person causing, or likely to cause, the harm from being in a specified place. It may have other conditions attached to it, and may last for a period of time not exceeding 6 months. The subject of the order may be a child or adult. Serious harm must be evidenced. In case of urgency, a council can apply to a justice of the peace of the commission area, as opposed to a sheriff, with different arrangements in place for this.
A39: DATE REPORTED
A40: =(A1&" – "&A3) -> Indicator 8a – Indicator 9a | C40: Cumulative number by end of quarter (eg January to March 2023)
A42: RATIONALE
A43: =(A1&" – "&A2) -> Indicator 8a – Indicator 8b | C43: Tells us about levels of activity and the volume of 'adults at risk' being supported with an Adult Support and Protection Plan in place.
A44: =(A3) -> Indicator 9a | C44: Tells us about workforce demands and use of legislative framework as applied to 'adults at risk'.

Sheet 10-11 ACTIONS TAKEN
A1: Indicator 10 | C1: ACTION TAKEN FOLLOWING INQUIRIES CONCLUDED WITHOUT THE USE OF INVESTIGATORY POWERS
A2: Indicator 11 | C2: ACTION TAKEN FOLLOWING INQUIRIES USING INVESTIGATORY POWERS
A4: LOCAL DATA
A5: =A1 -> Indicator 10 | C5: Apr-Jun | D5: Jul-Sep | E5: Oct-Dec | F5: Jan-Mar | G5: Apr-Jun | H5: Jul-Sep | I5: Oct-Dec | J5: Jan-Mar | K5: Apr-Jun | L5: Jul-Sep | M5: Oct-Dec | N5: Jan-Mar | O5: Apr-Jun | P5: Jul-Sep | Q5: Oct-Dec | R5: Jan-Mar | S5: Apr-Jun | T5: Jul-Sep | U5: Oct-Dec | V5: Jan-Mar | W5: Apr-Jun | X5: Jul-Sep | Y5: Oct-Dec | Z5: Jan-Mar | AA5: Apr-Jun | AB5: Jul-Sep | AC5: Oct-Dec | AD5: Jan-Mar | AE5: Apr-Jun | AF5: Jul-Sep | AG5: Oct-Dec | AH5: Jan-Mar | AI5: Apr-Jun | AJ5: Jul-Sep | AK5: Oct-Dec | AL5: Jan-Mar
C6: Q1 2023/24 | D6: Q2 2023/24 | E6: Q3 2023/24 | F6: Q4 2023/24 | G6: Q1 2024/25 | H6: Q2 2024/25 | I6: Q3 2024/25 | J6: Q4 2024/25 | K6: Q1 2025/26 | L6: Q2 2025/26 | M6: Q3 2025/26 | N6: Q4 2025/26 | O6: Q1 2026/27 | P6: Q2 2026/27 | Q6: Q3 2026/27 | R6: Q4 2026/27 | S6: Q1 2027/28 | T6: Q2 2027/28 | U6: Q3 2027/28 | V6: Q4 2027/28 | W6: Q1 2028/29 | X6: Q2 2028/29 | Y6: Q3 2028/29 | Z6: Q4 2028/29 | AA6: Q1 2029/30 | AB6: Q2 2029/30 | AC6: Q3 2029/30 | AD6: Q4 2029/30 | AE6: Q1 2030/31 | AF6: Q2 2030/31 | AG6: Q3 2030/31 | AH6: Q4 2030/31 | AI6: Q1 2031/32 | AJ6: Q2 2031/32 | AK6: Q3 2031/32 | AL6: Q4 2031/32
A7: Does not meet three-point criteria — NFA
A8: Does not meet three point criteria - non-ASP support provided or offered
A9: Meets three-point criteria — ongoing ASP work
A10: Meets three-point criteria — non-ASP support provided or offered
A11: Meets three-point criteria — no opportunity for further ASP intervention
A12: Pending/Unknown
A13: Total | C13: =SUM(C7:C12) -> 0 | D13: =SUM(D7:D12) -> 0 | E13: =SUM(E7:E12) -> 0 | F13: =SUM(F7:F12) -> 0 | G13: =SUM(G7:G12) -> 0 | H13: =SUM(H7:H12) -> 0 | I13: =SUM(I7:I12) -> 0 | J13: =SUM(J7:J12) -> 0 | ... AL13: =SUM(AL7:AL12) -> 0
A15: =A2 -> Indicator 11 | C15: Apr-Jun | D15: Jul-Sep | E15: Oct-Dec | F15: Jan-Mar | G15: Apr-Jun | H15: Jul-Sep | I15: Oct-Dec | J15: Jan-Mar | K15: Apr-Jun | L15: Jul-Sep | M15: Oct-Dec | N15: Jan-Mar | O15: Apr-Jun | P15: Jul-Sep | Q15: Oct-Dec | R15: Jan-Mar | S15: Apr-Jun | T15: Jul-Sep | U15: Oct-Dec | V15: Jan-Mar | W15: Apr-Jun | X15: Jul-Sep | Y15: Oct-Dec | Z15: Jan-Mar | AA15: Apr-Jun | AB15: Jul-Sep | AC15: Oct-Dec | AD15: Jan-Mar | AE15: Apr-Jun | AF15: Jul-Sep | AG15: Oct-Dec | AH15: Jan-Mar | AI15: Apr-Jun | AJ15: Jul-Sep | AK15: Oct-Dec | AL15: Jan-Mar
C16: Q1 2023/24 | D16: Q2 2023/24 | E16: Q3 2023/24 | F16: Q4 2023/24 | G16: Q1 2024/25 | H16: Q2 2024/25 | I16: Q3 2024/25 | J16: Q4 2024/25 | K16: Q1 2025/26 | L16: Q2 2025/26 | M16: Q3 2025/26 | N16: Q4 2025/26 | O16: Q1 2026/27 | P16: Q2 2026/27 | Q16: Q3 2026/27 | R16: Q4 2026/27 | S16: Q1 2027/28 | T16: Q2 2027/28 | U16: Q3 2027/28 | V16: Q4 2027/28 | W16: Q1 2028/29 | X16: Q2 2028/29 | Y16: Q3 2028/29 | Z16: Q4 2028/29 | AA16: Q1 2029/30 | AB16: Q2 2029/30 | AC16: Q3 2029/30 | AD16: Q4 2029/30 | AE16: Q1 2030/31 | AF16: Q2 2030/31 | AG16: Q3 2030/31 | AH16: Q4 2030/31 | AI16: Q1 2031/32 | AJ16: Q2 2031/32 | AK16: Q3 2031/32 | AL16: Q4 2031/32
A17: Does not meet three-point criteria — NFA
A18: Does not meet three point criteria - non-ASP support provided or offered
A19: Meets three-point criteria — ongoing ASP work
A20: Meets three-point criteria — non-ASP support provided or offered
A21: Meets three-point criteria — no opportunity for further ASP intervention
A22: Pending/Unknown
A23: Total | C23: =SUM(C17:C22) -> 0 | D23: =SUM(D17:D22) -> 0 | E23: =SUM(E17:E22) -> 0 | F23: =SUM(F17:F22) -> 0 | G23: =SUM(G17:G22) -> 0 | H23: =SUM(H17:H22) -> 0 | I23: =SUM(I17:I22) -> 0 | J23: =SUM(J17:J22) -> 0 | ... AL23: =SUM(AL17:AL22) -> 0
A25: Check Action taken matches number of inquiries without the use of investigatory powers | C25: =AND(EXACT(C13,'2-3 INQUIRIES'!C7)) -> FALSE | D25: =AND(EXACT(D13,'2-3 INQUIRIES'!D7)) -> FALSE | E25: =AND(EXACT(E13,'2-3 INQUIRIES'!E7)) -> FALSE | F25: =AND(EXACT(F13,'2-3 INQUIRIES'!F7)) -> FALSE | G25: =AND(EXACT(G13,'2-3 INQUIRIES'!G7)) -> FALSE | H25: =AND(EXACT(H13,'2-3 INQUIRIES'!H7)) -> FALSE | I25: =AND(EXACT(I13,'2-3 INQUIRIES'!I7)) -> FALSE | J25: =AND(EXACT(J13,'2-3 INQUIRIES'!J7)) -> FALSE | ... AL25: =AND(EXACT(AL13,'2-3 INQUIRIES'!AL7)) -> FALSE
A26: Check Action taken matches number of inquiries with the use of investigatory powers | C26: =AND(EXACT(C23,'2-3 INQUIRIES'!C11)) -> FALSE | D26: =AND(EXACT(D23,'2-3 INQUIRIES'!D11)) -> FALSE | E26: =AND(EXACT(E23,'2-3 INQUIRIES'!E11)) -> FALSE | F26: =AND(EXACT(F23,'2-3 INQUIRIES'!F11)) -> FALSE | G26: =AND(EXACT(G23,'2-3 INQUIRIES'!G11)) -> FALSE | H26: =AND(EXACT(H23,'2-3 INQUIRIES'!H11)) -> FALSE | I26: =AND(EXACT(I23,'2-3 INQUIRIES'!I11)) -> FALSE | J26: =AND(EXACT(J23,'2-3 INQUIRIES'!J11)) -> FALSE | ... AI26: =AND(EXACT(AI23,'2-3 INQUIRIES'!AI11)) -> FALSE | AJ26: =AND(EXACT(AJ13,'2-3 INQUIRIES'!AJ11)) -> FALSE | AK26: =AND(EXACT(AK13,'2-3 INQUIRIES'!AK11)) -> FALSE | AL26: =AND(EXACT(AL13,'2-3 INQUIRIES'!AL11)) -> FALSE
A27: REFLECTIONS AND CAVEATS
A28: Please use the free text field opposite to detail any challenges experienced in completing the above, and where additional clarification or amendments may be needed/helpful.
A30: SUGGESTED PRESENTATION
A33: NOTES ON COMPLETION
A34: =(A1&" – "&A2) -> Indicator 10 – Indicator 11 | C34: Please count all inquiries triggered in a quarter and record actions taken where these are known. Actions can be tracked up to the submission date you have been provided with for each quarterly data return. To illustrate: If 100 inquiries were begun in Quarter 1 (1 April - 30 June inclusive) we ask you to record what actions were taken, tracking these up to August 12th, the Scottish Government submission date for returns. Please select the action taken from the list of categories provided. We understand that there may be delays that result in actions taken being recorded as pending/unknown. We ask you to provide commentary in the free box on the reasons for delays eg. delay in receipt of financial records requested of other agencies as part of an inquiry.
A35: Does not meet three-point criteria — NFA | C35: This is where the adult does not meet the three point criteria, there is no requirement for any social work involvement and no requirement to refer to another agency ie. NFA.
A37: Meets three-point criteria — non-ASP support provided or offered | C37: Every time we intervene in a persons’ life we can only do so under a legislative framework. We might determine during an inquiry that the adult is an adult at risk (as defined under the ASPA) but it is not of benefit or it is the least restrictive option to continue that intervention under a different statute i.e. Social Work (Scotland) Act 1968. Illustrations This might include scenarios where: • the inquiry identifies that the person is better suited to support under the Adults with Incapacity (Scotland) Act 2000 by the statutory mental health team (MHOs), or • a new adult care assessment under self-directed support is agreed to complement support for the adult to manage risk, or • existing care management plans are deemed sufficient or can be supplemented with, for example, additional 1-1 support for an adult in a care home in increasing distress. In these situations, it would be closed to ASP and not managed by its processes despite meeting the three point criteria. However, we also recognise that practice in this area varies, and in some areas the case would remain under ASP - either as ongoing ASP work with the case proceeding to a case conference, or in situations where a person has died, it would be recorded as ‘no opportunity for further ASP intervention’.
